Workbook
Name ___: ForPullDownList!$A$2
Name _______: ForPullDownList!$A$26
Name _1A1B1: ForPullDownList!$K$75:$K$77
Name _1A1B2: ForPullDownList!$M$75:$M$77
Name ABCDEFG: ForPullDownList!$N$65:$N$71
Name PRTR2021区分: ForPullDownList!$A$118:$A$766
Name PRTR区分: ForPullDownList!$A$54:$A$57
Name ボンベサイズ: ForPullDownList!$I$88:$I$93
Name 医薬品: ForPullDownList!$A$97:$A$99
Name 医薬品____: ForPullDownList!$B$105
Name 医薬品_一般用医薬品: ForPullDownList!$C$105:$C$108
Name 医薬品_薬局医薬品: ForPullDownList!$D$105:$D$106
Name 医薬品_要指導医薬品: ForPullDownList!$E$105:$E$108
Name 医薬部外品: ForPullDownList!$B$97
Name 医薬部外品____: ForPullDownList!$F$105
Name 医療機器: ForPullDownList!$C$97:$C$100
Name 医療機器_クラスⅠ: ForPullDownList!$G$106
Name 医療機器_クラスⅡ: ForPullDownList!$H$105
Name 医療機器_クラスⅢ: ForPullDownList!$I$105
Name 医療機器_クラスⅣ: ForPullDownList!$J$105
Name 化粧品: ForPullDownList!$D$97
Name 化粧品____: ForPullDownList!$K$105
Name 可燃性又は引火性ガス: ForPullDownList!$C$65:$C$68
Name 管理方法: ForPullDownList!$P$38:$P$40
Name 眼刺激性: ForPullDownList!$I$75:$I$77
Name 期間単位: ForPullDownList!$O$54:$O$57
Name 権限: #REF!
Name 高圧ガス: ForPullDownList!$H$65:$H$68
Name 高圧ガス管理方法: ForPullDownList!$K$88:$K$89
Name 高圧ガス区分: ForPullDownList!$A$88:$A$92
Name 高圧ガス種別: ForPullDownList!$G$89:$G$91
Name 高圧ガス毒性: ForPullDownList!$E$88:$E$90
Name 高圧ガス燃焼性: ForPullDownList!$C$88:$C$91
Name 再生医療等製品: ForPullDownList!$E$97
Name 再生医療等製品____: ForPullDownList!$L$105
Name 指定可燃物: ForPullDownList!$H$2:$H$13
Name 指定可燃物____: ForPullDownList!$BK$26
Name 指定可燃物_ぼろ及び紙くず: ForPullDownList!$BN$26
Name 指定可燃物_わら類: ForPullDownList!$BP$26
Name 指定可燃物_可燃性液体類: ForPullDownList!$BT$26
Name 指定可燃物_可燃性固体類: ForPullDownList!$BR$26
Name 指定可燃物_合成樹脂類: ForPullDownList!$BV$26:$BV$27
Name 指定可燃物_再生資源燃料: ForPullDownList!$BQ$26
Name 指定可燃物_糸類: ForPullDownList!$BO$26
Name 指定可燃物_石炭・木炭類: ForPullDownList!$BS$26
Name 指定可燃物_綿花類: ForPullDownList!$BL$26
Name 指定可燃物_木材加工品及び木くず: ForPullDownList!$BU$26
Name 指定可燃物_木毛及びかんなくず: ForPullDownList!$BM$26
Name 指定数量_類別: ForPullDownList!$A$1:$H$1
Name 水濁法区分: ForPullDownList!$I$54:$I$55
Name 数字12: ForPullDownList!$L$65:$L$66
Name 数字123: ForPullDownList!$C$75:$C$77
Name 数字1234: ForPullDownList!$E$75:$E$78
Name 生殖毒性: ForPullDownList!$O$75:$O$77
Name 体外診断用医薬品: ForPullDownList!$F$97
Name 体外診断用医薬品____: ForPullDownList!$M$105
Name 大防法区分: ForPullDownList!$K$54:$K$58
Name 第1類: ForPullDownList!$B$2:$B$13
Name 第1類____: ForPullDownList!$B$26:$B$29
Name 第1類_その他のもので政令で定めるもの: ForPullDownList!$C$26:$C$28

Sheet ForPullDownList
A1: --- | B1: 第1類 | C1: 第2類 | D1: 第3類 | E1: 第4類 | F1: 第5類 | G1: 第6類 | H1: 指定可燃物
A2: --- | B2: --- | C2: --- | D2: --- | E2: --- | F2: --- | G2: --- | H2: ---
B3: その他のもので政令で定めるもの | C3: その他のもので政令で定めるもの | D3: その他のもので政令で定めるもの | E3: 特殊引火物 | F3: その他のもので政令で定めるもの | G3: その他のもので政令で定めるもの | H3: 綿花類
B4: 前各号に掲げるもののいずれかを含有するもの | C4: 前各号に掲げるもののいずれかを含有するもの | D4: 前各号に掲げるもののいずれかを含有するもの | E4: 第1石油類 | F4: 前各号に掲げるもののいずれかを含有するもの | G4: 前各号に掲げるもののいずれかを含有するもの | H4: 木毛及びかんなくず
B5: よう素酸塩類 | C5: マグネシウム | D5: アルカリ金属（カリウム及びナトリウムを除く）及びアルカリ土類金属 | E5: アルコール類 | F5: 有機過酸化物 | G5: 過塩素酸 | H5: ぼろ及び紙くず
B6: 亜塩素酸塩類 | C6: 引火性固体 | D6: 有機金属化合物（アルキルアルミニウム及びアルキルリチウムを除く） | E6: 第2石油類 | F6: 硝酸エステル類 | G6: 過酸化水素 | H6: 糸類
B7: 塩素酸塩類 | C7: 金属粉 | D7: 金属の水素化物 | E7: 第3石油類 | F7: ニトロ化合物 | G7: 硝酸 | H7: わら類
B8: 過マンガン酸塩類 | C8: 赤りん | D8: 金属のりん化物 | E8: 第4石油類 | F8: ニトロソ化合物 | H8: 再生資源燃料
B9: 過塩素酸塩類 | C9: 鉄粉 | D9: カルシウム又はアルミニウムの炭化物 | E9: 動植物油類 | F9: アゾ化合物 | H9: 可燃性固体類
B10: 臭素酸塩類 | C10: 硫黄 | D10: アルキルアルミニウム | F10: ジアゾ化合物 | H10: 石炭・木炭類
B11: 重クロム酸塩類 | C11: 硫化りん | D11: アルキルリチウム | F11: ヒドラジンの誘導体 | H11: 可燃性液体類
B12: 硝酸塩類 | D12: カリウム | F12: ヒドロキシルアミン | H12: 木材加工品及び木くず
B13: 無機過酸化物 | D13: ナトリウム | F13: ヒドロキシルアミン塩類 | H13: 合成樹脂類
D14: 黄りん
A24: --- | B24: 第1類 | N24: 第2類 | X24: 第3類 | AK24: 第4類 | AS24: 第5類 | BE24: 第6類 | BK24: 指定可燃物
A25: --- | B25: --- | C25: その他のもので政令で定めるもの | D25: 前各号に掲げるもののいずれかを含有するもの | E25: よう素酸塩類 | F25: 亜塩素酸塩類 | G25: 塩素酸塩類 | H25: 過マンガン酸塩類 | I25: 過塩素酸塩類 | J25: 臭素酸塩類 | K25: 重クロム酸塩類 | L25: 硝酸塩類 | M25: 無機過酸化物 | N25: --- | O25: その他のもので政令で定めるもの | P25: 前各号に掲げるもののいずれかを含有するもの | Q25: マグネシウム | R25: 引火性固体 | S25: 金属粉 | T25: 赤りん | U25: 鉄粉 | V25: 硫黄 | W25: 硫化りん | X25: --- | Y25: その他のもので政令で定めるもの | Z25: 前各号に掲げるもののいずれかを含有するもの | AA25: アルカリ金属（カリウム及びナトリウムを除く）及びアルカリ土類金属 | AB25: 有機金属化合物（アルキルアルミニウム及びアルキルリチウムを除く） | AC25: 金属の水素化物 | AD25: 金属のりん化物 | AE25: カルシウム又はアルミニウムの炭化物 | AF25: アルキルアルミニウム | AG25: アルキルリチウム | AH25: カリウム | AI25: ナトリウム | AJ25: 黄りん | AK25: --- | AL25: 特殊引火物 | AM25: 第1石油類 | AN25: アルコール類 | AO25: 第2石油類 | AP25: 第3石油類 | AQ25: 第4石油類 | AR25: 動植物油類 | AS25: --- | AT25: その他のもので政令で定めるもの | AU25: 前各号に掲げるもののいずれかを含有するもの | AV25: 有機過酸化物 | AW25: 硝酸エステル類 | AX25: ニトロ化合物 | AY25: ニトロソ化合物 | AZ25: アゾ化合物 | BA25: ジアゾ化合物 | BB25: ヒドラジンの誘導体 | BC25: ヒドロキシルアミン | BD25: ヒドロキシルアミン塩類 | BE25: --- | BF25: その他のもので政令で定めるもの | BG25: 前各号に掲げるもののいずれかを含有するもの | BH25: 過塩素酸 | BI25: 過酸化水素 | BJ25: 硝酸 | BK25: --- | BL25: 綿花類 | BM25: 木毛及びかんなくず | BN25: ぼろ及び紙くず | BO25: 糸類 | BP25: わら類 | BQ25: 再生資源燃料 | BR25: 可燃性固体類 | BS25: 石炭・木炭類 | BT25: 可燃性液体類 | BU25: 木材加工品及び木くず | BV25: 合成樹脂類
A26: --- | B26: --- | C26: 第1種 | D26: 第1種 | E26: 第1種 | F26: 第1種 | G26: 第1種 | H26: 第1種 | I26: 第1種 | J26: 第1種 | K26: 第1種 | L26: 第1種 | M26: 第1種 | N26: --- | O26: 第1種 | P26: 第1種 | Q26: 第1種 | S26: 第1種 | X26: --- | Y26: 第1種 | Z26: 第1種 | AA26: 第1種 | AB26: 第1種 | AC26: 第1種 | AD26: 第1種 | AE26: 第1種 | AK26: --- | AM26: 水溶性 | AO26: 水溶性 | AP26: 水溶性 | AS26: --- | AT26: 第1種 | AU26: 第1種 | AV26: 第1種 | AW26: 第1種 | AX26: 第1種 | AY26: 第1種 | AZ26: 第1種 | BA26: 第1種 | BB26: 第1種 | BC26: 第1種 | BD26: 第1種 | BE26: --- | BK26: --- | BV26: 発砲させたもの
B27: 第1種 | C27: 第2種 | D27: 第2種 | E27: 第2種 | F27: 第2種 | G27: 第2種 | H27: 第2種 | I27: 第2種 | J27: 第2種 | K27: 第2種 | L27: 第2種 | M27: 第2種 | O27: 第2種 | P27: 第2種 | Q27: 第2種 | S27: 第2種 | Y27: 第2種 | Z27: 第2種 | AA27: 第2種 | AB27: 第2種 | AC27: 第2種 | AD27: 第2種 | AE27: 第2種 | AM27: 非水溶性 | AO27: 非水溶性 | AP27: 非水溶性 | AS27: 第1種 | AT27: 第2種 | AU27: 第2種 | AV27: 第2種 | AW27: 第2種 | AX27: 第2種 | AY27: 第2種 | AZ27: 第2種 | BA27: 第2種 | BB27: 第2種 | BC27: 第2種 | BD27: 第2種 | BV27: その他のもの
B28: 第2種 | C28: 第3種 | D28: 第3種 | E28: 第3種 | F28: 第3種 | G28: 第3種 | H28: 第3種 | I28: 第3種 | J28: 第3種 | K28: 第3種 | L28: 第3種 | M28: 第3種 | Y28: 第3種 | Z28: 第3種 | AA28: 第3種 | AB28: 第3種 | AC28: 第3種 | AD28: 第3種 | AE28: 第3種 | AS28: 第2種
B29: 第3種
A37: 毒劇法区分 | C37: 編集可否1 | E37: 労安衛法特化則類別 | H37: 労安衛法特化則区分 | M37: 労安衛法有機則種別 | P37: 管理方法 | S37: 保管場所 | U37: 所属 | W37: カスタム法規1 | Y37: カスタム法規2 | AA37: メーカー | AC37: メーカーリスト | AE37: フラグリスト | AG37: 権限 | AI37: ユーザー | AK37: カスタム法規3 | AM37: カスタム法規4 | AO37: カスタム法規5 | AQ37: カスタム法規6
A38: 毒物 | C38: 閲覧・編集 | E38: 第1類 | H38: 労安衛法特化則_第1類 | I38: 労安衛法特化則_第2類 | J38: 労安衛法特化則_第3類 | M38: 第1種 | P38: 重量管理 | S38: =MAX(INDEX((LEN(#REF!)>0)*ROW(#REF!),0))-2 -> #REF! | U38: {=MAX(INDEX((LEN(#REF!)>0)*ROW(#REF!),0))-2} -> #REF! | W38: =MAX(INDEX((LEN(#REF!)>0)*ROW(#REF!),0))-5 -> #REF! | Y38: =MAX(INDEX((LEN(#REF!)>0)*ROW(#REF!),0))-5 -> #REF! | AA38: =MAX(INDEX((LEN(#REF!)>0)*ROW(#REF!),0))-2 -> #REF! | AG38: {=MAX(INDEX((LEN(#REF!)>0)*ROW(#REF!),0))-2} -> #REF! | AI38: {=MAX(INDEX((LEN(#REF!)>0)*ROW(#REF!),0))-3} -> #REF! | AK38: {=MAX(INDEX((LEN(#REF!)>0)*ROW(#REF!),0))-5} -> #REF! | AM38: {=MAX(INDEX((LEN(#REF!)>0)*ROW(#REF!),0))-5} -> #REF! | AO38: {=MAX(INDEX((LEN(#REF!)>0)*ROW(#REF!),0))-5} -> #REF! | AQ38: {=MAX(INDEX((LEN(#REF!)>0)*ROW(#REF!),0))-5} -> #REF!
A39: 劇物 | C39: 不可 | E39: 第2類 | I39: 特定 | M39: 第2種 | P39: 本数管理 | S39: =#REF!&"／"&#REF!&"／"&#REF! -> #REF! | U39: =#REF!&"／"&#REF!&"／"&#REF! -> #REF! | W39: =#REF!&"／"&#REF!&"／"&#REF! -> #REF! | Y39: =#REF!&"／"&#REF!&"／"&#REF! -> #REF! | AA39: =#REF! -> #REF! | AB39: =IF(COUNTIF($AA$39:AA39,AA39)=1,ROW(),"") -> 39 | AC39: =IF(COUNT($AB$39:$AB$100)>=ROW()-38,INDEX($AA$39:$AA$100,MATCH(SMALL($AB$39:$AB$100,ROW(A1)),$AB$39:$AB$100,0)),"") -> #REF! | AE39: 0 | AG39: =#REF! -> #REF! | AI39: =#REF! -> #REF! | AK39: =#REF!&"／"&#REF!&"／"&#REF! -> #REF! | AM39: =#REF!&"／"&#REF!&"／"&#REF! -> #REF! | AO39: =#REF!&"／"&#REF!&"／"&#REF! -> #REF! | AQ39: =#REF!&"／"&#REF!&"／"&#REF! -> #REF!
A40: 特定毒物 | E40: 第3類 | I40: オーラミン等 | M40: 第3種 | P40: 指定なし | S40: =#REF!&"／"&#REF!&"／"&#REF! -> #REF! | U40: =#REF!&"／"&#REF!&"／"&#REF! -> #REF! | W40: =#REF!&"／"&#REF!&"／"&#REF! -> #REF! | Y40: =#REF!&"／"&#REF!&"／"&#REF! -> #REF! | AA40: =#REF! -> #REF! | AB40: =IF(COUNTIF($AA$39:AA40,AA40)=1,ROW(),"") | AC40: =IF(COUNT($AB$39:$AB$100)>=ROW()-38,INDEX($AA$39:$AA$100,MATCH(SMALL($AB$39:$AB$100,ROW(A2)),$AB$39:$AB$100,0)),"") | AE40: 1 | AG40: =#REF! -> #REF! | AI40: =#REF! -> #REF! | AK40: =#REF!&"／"&#REF!&"／"&#REF! -> #REF! | AM40: =#REF!&"／"&#REF!&"／"&#REF! -> #REF! | AO40: =#REF!&"／"&#REF!&"／"&#REF! -> #REF! | AQ40: =#REF!&"／"&#REF!&"／"&#REF! -> #REF!
C41: 編集可否2 | I41: 特別有機溶剤等 | S41: =#REF!&"／"&#REF!&"／"&#REF! -> #REF! | U41: =#REF!&"／"&#REF!&"／"&#REF! -> #REF! | W41: =#REF!&"／"&#REF!&"／"&#REF! -> #REF! | Y41: =#REF!&"／"&#REF!&"／"&#REF! -> #REF! | AA41: =#REF! -> #REF! | AB41: =IF(COUNTIF($AA$39:AA41,AA41)=1,ROW(),"") | AC41: =IF(COUNT($AB$39:$AB$100)>=ROW()-38,INDEX($AA$39:$AA$100,MATCH(SMALL($AB$39:$AB$100,ROW(A3)),$AB$39:$AB$100,0)),"") | AG41: =#REF! -> #REF! | AI41: =#REF! -> #REF! | AK41: =#REF!&"／"&#REF!&"／"&#REF! -> #REF! | AM41: =#REF!&"／"&#REF!&"／"&#REF! -> #REF! | AO41: =#REF!&"／"&#REF!&"／"&#REF! -> #REF! | AQ41: =#REF!&"／"&#REF!&"／"&#REF! -> #REF!
C42: 閲覧・編集 | I42: 管理 | S42: =#REF!&"／"&#REF!&"／"&#REF! -> #REF! | U42: =#REF!&"／"&#REF!&"／"&#REF! -> #REF! | W42: =#REF!&"／"&#REF!&"／"&#REF! -> #REF! | Y42: =#REF!&"／"&#REF!&"／"&#REF! -> #REF! | AA42: =#REF! -> #REF! | AB42: =IF(COUNTIF($AA$39:AA42,AA42)=1,ROW(),"") | AC42: =IF(COUNT($AB$39:$AB$100)>=ROW()-38,INDEX($AA$39:$AA$100,MATCH(SMALL($AB$39:$AB$100,ROW(A4)),$AB$39:$AB$100,0)),"") | AG42: =#REF! -> #REF! | AI42: =#REF! -> #REF! | AK42: =#REF!&"／"&#REF!&"／"&#REF! -> #REF! | AM42: =#REF!&"／"&#REF!&"／"&#REF! -> #REF! | AO42: =#REF!&"／"&#REF!&"／"&#REF! -> #REF! | AQ42: =#REF!&"／"&#REF!&"／"&#REF! -> #REF!
C43: 閲覧のみ | S43: =#REF!&"／"&#REF!&"／"&#REF! -> #REF! | U43: =#REF!&"／"&#REF!&"／"&#REF! -> #REF! | W43: =#REF!&"／"&#REF!&"／"&#REF! -> #REF! | Y43: =#REF!&"／"&#REF!&"／"&#REF! -> #REF! | AA43: =#REF! -> #REF! | AB43: =IF(COUNTIF($AA$39:AA43,AA43)=1,ROW(),"") | AC43: =IF(COUNT($AB$39:$AB$100)>=ROW()-38,INDEX($AA$39:$AA$100,MATCH(SMALL($AB$39:$AB$100,ROW(A5)),$AB$39:$AB$100,0)),"") | AG43: =#REF! -> #REF! | AI43: =#REF! -> #REF! | AK43: =#REF!&"／"&#REF!&"／"&#REF! -> #REF! | AM43: =#REF!&"／"&#REF!&"／"&#REF! -> #REF! | AO43: =#REF!&"／"&#REF!&"／"&#REF! -> #REF! | AQ43: =#REF!&"／"&#REF!&"／"&#REF! -> #REF!
C44: 不可 | S44: =#REF!&"／"&#REF!&"／"&#REF! -> #REF! | U44: =#REF!&"／"&#REF!&"／"&#REF! -> #REF! | W44: =#REF!&"／"&#REF!&"／"&#REF! -> #REF! | Y44: =#REF!&"／"&#REF!&"／"&#REF! -> #REF! | AA44: =#REF! -> #REF! | AB44: =IF(COUNTIF($AA$39:AA44,AA44)=1,ROW(),"") | AC44: =IF(COUNT($AB$39:$AB$100)>=ROW()-38,INDEX($AA$39:$AA$100,MATCH(SMALL($AB$39:$AB$100,ROW(A6)),$AB$39:$AB$100,0)),"") | AG44: =#REF! -> #REF! | AI44: =#REF! -> #REF! | AK44: =#REF!&"／"&#REF!&"／"&#REF! -> #REF! | AM44: =#REF!&"／"&#REF!&"／"&#REF! -> #REF! | AO44: =#REF!&"／"&#REF!&"／"&#REF! -> #REF! | AQ44: =#REF!&"／"&#REF!&"／"&#REF! -> #REF!
S45: =#REF!&"／"&#REF!&"／"&#REF! -> #REF! | U45: =#REF!&"／"&#REF!&"／"&#REF! -> #REF! | W45: =#REF!&"／"&#REF!&"／"&#REF! -> #REF! | Y45: =#REF!&"／"&#REF!&"／"&#REF! -> #REF! | AA45: =#REF! -> #REF! | AB45: =IF(COUNTIF($AA$39:AA45,AA45)=1,ROW(),"") | AC45: =IF(COUNT($AB$39:$AB$100)>=ROW()-38,INDEX($AA$39:$AA$100,MATCH(SMALL($AB$39:$AB$100,ROW(A7)),$AB$39:$AB$100,0)),"") | AG45: =#REF! -> #REF! | AI45: =#REF! -> #REF! | AK45: =#REF!&"／"&#REF!&"／"&#REF! -> #REF! | AM45: =#REF!&"／"&#REF!&"／"&#REF! -> #REF! | AO45: =#REF!&"／"&#REF!&"／"&#REF! -> #REF! | AQ45: =#REF!&"／"&#REF!&"／"&#REF! -> #REF!
C46: 編集可否3 | S46: =#REF!&"／"&#REF!&"／"&#REF! -> #REF! | U46: =#REF!&"／"&#REF!&"／"&#REF! -> #REF! | W46: =#REF!&"／"&#REF!&"／"&#REF! -> #REF! | Y46: =#REF!&"／"&#REF!&"／"&#REF! -> #REF! | AA46: =#REF! -> #REF! | AB46: =IF(COUNTIF($AA$39:AA46,AA46)=1,ROW(),"") | AC46: =IF(COUNT($AB$39:$AB$100)>=ROW()-38,INDEX($AA$39:$AA$100,MATCH(SMALL($AB$39:$AB$100,ROW(A8)),$AB$39:$AB$100,0)),"") | AG46: =#REF! -> #REF! | AI46: =#REF! -> #REF! | AK46: =#REF!&"／"&#REF!&"／"&#REF! -> #REF! | AM46: =#REF!&"／"&#REF!&"／"&#REF! -> #REF! | AO46: =#REF!&"／"&#REF!&"／"&#REF! -> #REF! | AQ46: =#REF!&"／"&#REF!&"／"&#REF! -> #REF!
C47: 可 | S47: =#REF!&"／"&#REF!&"／"&#REF! -> #REF! | U47: =#REF!&"／"&#REF!&"／"&#REF! -> #REF! | W47: =#REF!&"／"&#REF!&"／"&#REF! -> #REF! | Y47: =#REF!&"／"&#REF!&"／"&#REF! -> #REF! | AA47: =#REF! -> #REF! | AB47: =IF(COUNTIF($AA$39:AA47,AA47)=1,ROW(),"") | AC47: =IF(COUNT($AB$39:$AB$100)>=ROW()-38,INDEX($AA$39:$AA$100,MATCH(SMALL($AB$39:$AB$100,ROW(A9)),$AB$39:$AB$100,0)),"") | AG47: =#REF! -> #REF! | AI47: =#REF! -> #REF! | AK47: =#REF!&"／"&#REF!&"／"&#REF! -> #REF! | AM47: =#REF!&"／"&#REF!&"／"&#REF! -> #REF! | AO47: =#REF!&"／"&#REF!&"／"&#REF! -> #REF! | AQ47: =#REF!&"／"&#REF!&"／"&#REF! -> #REF!
C48: 不可 | S48: =#REF!&"／"&#REF!&"／"&#REF! -> #REF! | U48: =#REF!&"／"&#REF!&"／"&#REF! -> #REF! | W48: =#REF!&"／"&#REF!&"／"&#REF! -> #REF! | Y48: =#REF!&"／"&#REF!&"／"&#REF! -> #REF! | AA48: =#REF! -> #REF! | AB48: =IF(COUNTIF($AA$39:AA48,AA48)=1,ROW(),"") | AC48: =IF(COUNT($AB$39:$AB$100)>=ROW()-38,INDEX($AA$39:$AA$100,MATCH(SMALL($AB$39:$AB$100,ROW(A10)),$AB$39:$AB$100,0)),"") | AG48: =#REF! -> #REF! | AI48: =#REF! -> #REF! | AK48: =#REF!&"／"&#REF!&"／"&#REF! -> #REF! | AM48: =#REF!&"／"&#REF!&"／"&#REF! -> #REF! | AO48: =#REF!&"／"&#REF!&"／"&#REF! -> #REF! | AQ48: =#REF!&"／"&#REF!&"／"&#REF! -> #REF!
S49: =#REF!&"／"&#REF!&"／"&#REF! -> #REF! | U49: =#REF!&"／"&#REF!&"／"&#REF! -> #REF! | W49: =#REF!&"／"&#REF!&"／"&#REF! -> #REF! | Y49: =#REF!&"／"&#REF!&"／"&#REF! -> #REF! | AA49: =#REF! -> #REF! | AB49: =IF(COUNTIF($AA$39:AA49,AA49)=1,ROW(),"") | AC49: =IF(COUNT($AB$39:$AB$100)>=ROW()-38,INDEX($AA$39:$AA$100,MATCH(SMALL($AB$39:$AB$100,ROW(A11)),$AB$39:$AB$100,0)),"") | AG49: =#REF! -> #REF! | AI49: =#REF! -> #REF! | AK49: =#REF!&"／"&#REF!&"／"&#REF! -> #REF! | AM49: =#REF!&"／"&#REF!&"／"&#REF! -> #REF! | AO49: =#REF!&"／"&#REF!&"／"&#REF! -> #REF! | AQ49: =#REF!&"／"&#REF!&"／"&#REF! -> #REF!
S50: =#REF!&"／"&#REF!&"／"&#REF! -> #REF! | U50: =#REF!&"／"&#REF!&"／"&#REF! -> #REF! | W50: =#REF!&"／"&#REF!&"／"&#REF! -> #REF! | Y50: =#REF!&"／"&#REF!&"／"&#REF! -> #REF! | AA50: =#REF! -> #REF! | AB50: =IF(COUNTIF($AA$39:AA50,AA50)=1,ROW(),"") | AC50: =IF(COUNT($AB$39:$AB$100)>=ROW()-38,INDEX($AA$39:$AA$100,MATCH(SMALL($AB$39:$AB$100,ROW(A12)),$AB$39:$AB$100,0)),"") | AG50: =#REF! -> #REF! | AI50: =#REF! -> #REF! | AK50: =#REF!&"／"&#REF!&"／"&#REF! -> #REF! | AM50: =#REF!&"／"&#REF!&"／"&#REF! -> #REF! | AO50: =#REF!&"／"&#REF!&"／"&#REF! -> #REF! | AQ50: =#REF!&"／"&#REF!&"／"&#REF! -> #REF!
S51: =#REF!&"／"&#REF!&"／"&#REF! -> #REF! | U51: =#REF!&"／"&#REF!&"／"&#REF! -> #REF! | W51: =#REF!&"／"&#REF!&"／"&#REF! -> #REF! | Y51: =#REF!&"／"&#REF!&"／"&#REF! -> #REF! | AA51: =#REF! -> #REF! | AB51: =IF(COUNTIF($AA$39:AA51,AA51)=1,ROW(),"") | AC51: =IF(COUNT($AB$39:$AB$100)>=ROW()-38,INDEX($AA$39:$AA$100,MATCH(SMALL($AB$39:$AB$100,ROW(A13)),$AB$39:$AB$100,0)),"") | AG51: =#REF! -> #REF! | AI51: =#REF! -> #REF! | AK51: =#REF!&"／"&#REF!&"／"&#REF! -> #REF! | AM51: =#REF!&"／"&#REF!&"／"&#REF! -> #REF! | AO51: =#REF!&"／"&#REF!&"／"&#REF! -> #REF! | AQ51: =#REF!&"／"&#REF!&"／"&#REF! -> #REF!
S52: =#REF!&"／"&#REF!&"／"&#REF! -> #REF! | U52: =#REF!&"／"&#REF!&"／"&#REF! -> #REF! | W52: =#REF!&"／"&#REF!&"／"&#REF! -> #REF! | Y52: =#REF!&"／"&#REF!&"／"&#REF! -> #REF! | AA52: =#REF! -> #REF! | AB52: =IF(COUNTIF($AA$39:AA52,AA52)=1,ROW(),"") | AC52: =IF(COUNT($AB$39:$AB$100)>=ROW()-38,INDEX($AA$39:$AA$100,MATCH(SMALL($AB$39:$AB$100,ROW(A14)),$AB$39:$AB$100,0)),"") | AG52: =#REF! -> #REF! | AI52: =#REF! -> #REF! | AK52: =#REF!&"／"&#REF!&"／"&#REF! -> #REF! | AM52: =#REF!&"／"&#REF!&"／"&#REF! -> #REF! | AO52: =#REF!&"／"&#REF!&"／"&#REF! -> #REF! | AQ52: =#REF!&"／"&#REF!&"／"&#REF! -> #REF!
A53: PRTR区分 | F53: 麻薬及び向精神薬取締法区分 | I53: 水濁法区分 | K53: 大防法区分 | O53: 期間単位 | Q53: 密度単位 | S53: =#REF!&"／"&#REF!&"／"&#REF! -> #REF! | U53: =#REF!&"／"&#REF!&"／"&#REF! -> #REF! | W53: =#REF!&"／"&#REF!&"／"&#REF! -> #REF! | Y53: =#REF!&"／"&#REF!&"／"&#REF! -> #REF! | AA53: =#REF! -> #REF! | AB53: =IF(COUNTIF($AA$39:AA53,AA53)=1,ROW(),"") | AC53: =IF(COUNT($AB$39:$AB$100)>=ROW()-38,INDEX($AA$39:$AA$100,MATCH(SMALL($AB$39:$AB$100,ROW(A15)),$AB$39:$AB$100,0)),"") | AG53: =#REF! -> #REF! | AI53: =#REF! -> #REF! | AK53: =#REF!&"／"&#REF!&"／"&#REF! -> #REF! | AM53: =#REF!&"／"&#REF!&"／"&#REF! -> #REF! | AO53: =#REF!&"／"&#REF!&"／"&#REF! -> #REF! | AQ53: =#REF!&"／"&#REF!&"／"&#REF! -> #REF!
A54: 第1種 | F54: 特定麻薬向精神薬原料 | I54: 有害物質 | K54: 揮発性有機化合物（VOC） | O54: 日 | Q54: g/ml | S54: =#REF!&"／"&#REF!&"／"&#REF! -> #REF! | U54: =#REF!&"／"&#REF!&"／"&#REF! -> #REF! | W54: =#REF!&"／"&#REF!&"／"&#REF! -> #REF! | Y54: =#REF!&"／"&#REF!&"／"&#REF! -> #REF! | AA54: =#REF! -> #REF! | AB54: =IF(COUNTIF($AA$39:AA54,AA54)=1,ROW(),"") | AC54: =IF(COUNT($AB$39:$AB$100)>=ROW()-38,INDEX($AA$39:$AA$100,MATCH(SMALL($AB$39:$AB$100,ROW(A16)),$AB$39:$AB$100,0)),"") | AG54: =#REF! -> #REF! | AI54: =#REF! -> #REF! | AK54: =#REF!&"／"&#REF!&"／"&#REF! -> #REF! | AM54: =#REF!&"／"&#REF!&"／"&#REF! -> #REF! | AO54: =#REF!&"／"&#REF!&"／"&#REF! -> #REF! | AQ54: =#REF!&"／"&#REF!&"／"&#REF! -> #REF!
A55: 特定第1種 | F55: 麻薬向精神薬原料 | I55: 指定物質 | K55: 有害大気汚染物質 | O55: 週 | Q55: g/l | S55: =#REF!&"／"&#REF!&"／"&#REF! -> #REF! | U55: =#REF!&"／"&#REF!&"／"&#REF! -> #REF! | W55: =#REF!&"／"&#REF!&"／"&#REF! -> #REF! | Y55: =#REF!&"／"&#REF!&"／"&#REF! -> #REF! | AA55: =#REF! -> #REF! | AB55: =IF(COUNTIF($AA$39:AA55,AA55)=1,ROW(),"") | AC55: =IF(COUNT($AB$39:$AB$100)>=ROW()-38,INDEX($AA$39:$AA$100,MATCH(SMALL($AB$39:$AB$100,ROW(A17)),$AB$39:$AB$100,0)),"") | AG55: =#REF! -> #REF! | AI55: =#REF! -> #REF! | AK55: =#REF!&"／"&#REF!&"／"&#REF! -> #REF! | AM55: =#REF!&"／"&#REF!&"／"&#REF! -> #REF! | AO55: =#REF!&"／"&#REF!&"／"&#REF! -> #REF! | AQ55: =#REF!&"／"&#REF!&"／"&#REF! -> #REF!
A56: 第2種 | F56: 麻薬 | K56: 有害大気汚染物質-優先取組 | O56: 月 | S56: =#REF!&"／"&#REF!&"／"&#REF! -> #REF! | U56: =#REF!&"／"&#REF!&"／"&#REF! -> #REF! | W56: =#REF!&"／"&#REF!&"／"&#REF! -> #REF! | Y56: =#REF!&"／"&#REF!&"／"&#REF! -> #REF! | AA56: =#REF! -> #REF! | AB56: =IF(COUNTIF($AA$39:AA56,AA56)=1,ROW(),"") | AC56: =IF(COUNT($AB$39:$AB$100)>=ROW()-38,INDEX($AA$39:$AA$100,MATCH(SMALL($AB$39:$AB$100,ROW(A18)),$AB$39:$AB$100,0)),"") | AG56: =#REF! -> #REF! | AI56: =#REF! -> #REF! | AK56: =#REF!&"／"&#REF!&"／"&#REF! -> #REF! | AM56: =#REF!&"／"&#REF!&"／"&#REF! -> #REF! | AO56: =#REF!&"／"&#REF!&"／"&#REF! -> #REF! | AQ56: =#REF!&"／"&#REF!&"／"&#REF! -> #REF!
...

Sheet Chemical
A1: JANコード (※製品ラベルに印字されているバーコードまたはQRコードの値) | B1: メーカー名 | C1: 型番 | D1: 薬品名(和名) | E1: 薬品名(英名) | F1: CAS番号 (※複数の場合は半角カンマ区切り) | G1: 規格 | H1: カタログ重量(数値) | I1: カタログ重量(単位) | J1: カタログ価格 | K1: 密度(数値) | L1: 密度(単位) | M1: 保管状態 | N1: 管理方法 | O1: 化学式 | P1: 分子量 | Q1: SDSファイル名またはURL | R1: 毒劇法 区分 | S1: 労働安全衛生法(特化則) 類別 | T1: 労働安全衛生法(特化則) 区分 | U1: 労働安全衛生法(特化則) 特別管理物質 | V1: 労働安全衛生法 リスクアセスメント対象 | W1: 労働安全衛生法 がん原性指針対象 | X1: 労働安全衛生法 がん原性物質 | Y1: 労働安全衛生法(有機則) 種別 | Z1: 労働安全衛生法(不浸透性の保護具等の使用義務物質) 区分 | AA1: 消防法 指定数量(類別) | AB1: 消防法 指定数量(品名) | AC1: 消防法 指定数量(種別) | AD1: PRTR制度① 区分 | AE1: PRTR制度① 号番号 | AF1: PRTR制度① 濃度(%) | AG1: PRTR制度② 区分 | AH1: PRTR制度② 号番号 | AI1: PRTR制度② 濃度(%) | AJ1: PRTR制度（2021年改正）① 区分 | AK1: PRTR制度（2021年改正）① 濃度(%) | AL1: PRTR制度（2021年改正）② 区分 | AM1: PRTR制度（2021年改正）② 濃度(%) | AN1: PRTR制度（2021年改正）③ 区分 | AO1: PRTR制度（2021年改正）③ 濃度(%) | AP1: PRTR制度 金属換算係数(数値) | AQ1: 薬機法 大区分 | AR1: 薬機法 中区分 | AS1: 薬機法 小区分 | AT1: 麻薬及び向精神薬取締法 区分 | AU1: 水質汚濁防止法 区分 | AV1: 大気汚染防止法① 区分 | AW1: 大気汚染防止法② 区分 | AX1: ユーザー定義法規① 区分 | AY1: ユーザー定義法規② 区分 | AZ1: ユーザー定義法規③ 区分 | BA1: ユーザー定義法規④ 区分 | BB1: ユーザー定義法規⑤ 区分 | BC1: ユーザー定義法規⑥ 区分 | BD1: 開封前使用期限 (数値) | BE1: 開封前使用期限 (単位) | BF1: 開封後使用期限 (数値) | BG1: 開封後使用期限 (単位) | BH1: 在庫基準数 | BI1: 廃棄方法 | BJ1: 保管場所① | BK1: 保管場所①-在庫基準数 | BL1: 保管場所①-在庫上限 | BM1: 保管場所①-通知先 | BN1: 保管場所② | BO1: 保管場所②-在庫基準数 | BP1: 保管場所②-在庫上限 | BQ1: 保管場所②-通知先 | BR1: 保管場所③ | BS1: 保管場所③-在庫基準数 | BT1: 保管場所③-在庫上限 | BU1: 保管場所③-通知先 | BV1: 保管場所④ | BW1: 保管場所④-在庫基準数 | BX1: 保管場所④-在庫上限 | BY1: 保管場所④-通知先 | BZ1: 保管場所⑤ | CA1: 保管場所⑤-在庫基準数 | CB1: 保管場所⑤-在庫上限 | CC1: 保管場所⑤-通知先 | CD1: 納入業者名 | CE1: その他ファイルまたはURL | CF1: 備考 | CG1: ラベルテンプレート | CH1: 承認要否 | CI1: 所属1 | CJ1: 所属2 | CK1: 所属3 | CL1: GHS 物理化学的危険性 | DC1: GHS 健康有害性 | DT1: GHS 環境有害性
A2: ※32文字以下 | B2: ※必須 | C2: ※必須 ※32文字以下 | D2: ※必須 ※128文字以下 | E2: ※必須 ※128文字以下 | F2: ※126文字以下 | G2: ※32文字以下 | H2: ※10文字以下 (小数第3位まで) (半角数字、小数点のみ) | I2: ※8文字以下 | J2: ※10文字以下 (整数かつ半角数字のみ) | K2: ※10桁以下 (小数第3位まで) (半角数字、小数点のみ) | L2: ※「g/ml」、「g/l」のいずれか | M2: ※64文字以下 | N2: ※「重量管理」、「本数管理」、「指定なし」のいずれか | O2: ※100文字以下 | P2: ※10桁以下 (小数第2位まで) (半角数字、小数点のみ) | Q2: ※1024文字以下 | R2: ※「毒物」、「劇物」、「特定毒物」のいずれか (該当しない場合は空欄) | S2: ※「第１類」、「第２類」、「第３類」のいずれか (該当しない場合は空欄) | T2: ※リストから選択 (該当しない場合は空欄) | U2: ※該当する場合は「○」、該当しない場合は空欄 | V2: ※対象の場合は「○」、非対象の場合は空欄 | W2: ※対象の場合は「○」、非対象の場合は空欄 | X2: ※対象の場合は「○」、非対象の場合は空欄 | Y2: ※リストから選択 (該当しない場合は空欄) | Z2: ※リストから選択 (該当しない場合は空欄) | AA2: ※リストから選択 (該当しない場合は空欄) | AB2: ※リストから選択 (該当しない場合は空欄) | AC2: ※リストから選択 (該当しない場合は空欄) | AD2: ※リストから選択 (該当しない場合は空欄) | AE2: ※3文字以下 (整数かつ半角数字のみ) | AF2: ※0以上100以下 (整数かつ半角数字のみ) | AG2: ※リストから選択 (該当しない場合は空欄) | AH2: ※3文字以下 (整数かつ半角数字のみ) | AI2: ※0以上100以下 (整数かつ半角数字のみ) | AJ2: ※リストから選択 (該当しない場合は空欄) | AK2: ※0以上100以下 (整数かつ半角数字のみ) | AL2: ※リストから選択 (該当しない場合は空欄) | AM2: ※0以上100以下 (整数かつ半角数字のみ) | AN2: ※リストから選択 (該当しない場合は空欄) | AO2: ※0以上100以下 (整数かつ半角数字のみ) | AP2: ※10桁以下 (小数点第3位まで) (半角数字、小数点のみ) | AQ2: ※リストから選択 (該当しない場合は空欄) | AR2: ※リストから選択 (該当しない場合は空欄) | AS2: ※リストから選択 (該当しない場合は空欄) | AT2: ※リストから選択 (該当しない場合は空欄) | AU2: ※「有害物質」、「指定物質」のいずれか (該当しない場合は空欄) | AV2: ※リストから選択 (該当しない場合は空欄) | AW2: ※リストから選択 (該当しない場合は空欄) | AX2: ※リストから選択 ※「CustomLaw1」に記入した内容が候補に表示されます | AY2: ※リストから選択 ※「CustomLaw2」に記入した内容が候補に表示されます | AZ2: ※リストから選択 ※「CustomLaw3」に記入した内容が候補に表示されます | BA2: ※リストから選択 ※「CustomLaw4」に記入した内容が候補に表示されます | BB2: ※リストから選択 ※「CustomLaw5」に記入した内容が候補に表示されます | BC2: ※リストから選択 ※「CustomLaw6」に記入した内容が候補に表示されます | BD2: ※3文字以下 (整数かつ半角数字のみ) | BE2: ※「日」「週」「月」「年」のいずれか | BF2: ※3文字以下 (整数かつ半角数字のみ) | BG2: ※「日」「週」「月」「年」のいずれか | BH2: ※5文字以下 (整数かつ半角数字のみ) | BI2: ※256文字以下 | BJ2: ※保管庫、棚、段位置を「／」区切り ※「Storage」シートに記入した内容が候補に表示されます ※更新を選択すると保管場所1～5を一括更新します | BK2: ※5文字以下 (整数かつ半角数字のみ) | BL2: ※5文字以下 (整数かつ半角数字のみ) | BM2: ※256文字以下 ※メールアドレスカンマ区切り | BN2: ※保管庫、棚、段位置を「／」区切り ※「Storage」シートに記入した内容が候補に表示されます | BO2: ※5文字以下 (整数かつ半角数字のみ) | BP2: ※5文字以下 (整数かつ半角数字のみ) | BQ2: ※256文字以下 ※メールアドレスカンマ区切り | BR2: ※保管庫、棚、段位置を「／」区切り ※「Storage」シートに記入した内容が候補に表示されます | BS2: ※5文字以下 (整数かつ半角数字のみ) | BT2: ※5文字以下 (整数かつ半角数字のみ) | BU2: ※256文字以下 ※メールアドレスカンマ区切り | BV2: ※保管庫、棚、段位置を「／」区切り ※「Storage」シートに記入した内容が候補に表示されます | BW2: ※5文字以下 (整数かつ半角数字のみ) | BX2: ※5文字以下 (整数かつ半角数字のみ) | BY2: ※256文字以下 ※メールアドレスカンマ区切り | BZ2: ※保管庫、棚、段位置を「／」区切り ※「Storage」シートに記入した内容が候補に表示されます | CA2: ※5文字以下 (整数かつ半角数字のみ) | CB2: ※5文字以下 (整数かつ半角数字のみ) | CC2: ※256文字以下 ※メールアドレスカンマ区切り | CD2: ※「Supplier」シートに記入した内容が候補に表示されます | CE2: ※1024文字以下 | CF2: ※256文字以下 | CG2: ※「標準」「小ビン」「カスタム」のいずれか | CH2: ※「必要」「不要」のいずれか | CI2: ※組織、部署、課を「／」区切り ※「Belonging」に記入した内容が候補に表示されます ※更新を選択すると所属1～3を一括更新します | CJ2: ※組織、部署、課を「／」区切り ※「Belonging」に記入した内容が候補に表示されます | CK2: ※組織、部署、課を「／」区切り ※「Belonging」に記入した内容が候補に表示されます | CL2: 爆発物 ※「不安定爆発物」、「等級1.1」、「等級1.2」、「等級1.3」、「等級1.4」、「等級1.5」、「等級1.6」のいずれか （該当しない場合は空欄） | CM2: 可燃性ガス ※「1」、「2」、「A」、「B」のいずれか （該当しない場合は空欄） | CN2: エアゾール ※「1」、「2」、「3」のいずれか （該当しない場合は空欄） | CO2: 酸化性ガス ※「1」 （該当しない場合は空欄） | CP2: 高圧ガス ※「圧縮ガス」、「液化ガス」、「深冷液化ガス」、「溶解ガス」のいずれか （該当しない場合は空欄） | CQ2: 引火性液体 ※「1」、「2」、「3」、「4」のいずれか （該当しない場合は空欄） | CR2: 可燃性固体 ※「1」、「2」のいずれか （該当しない場合は空欄） | CS2: 自己反応性化学品 ※「タイプA」、「タイプB」、「タイプC」、「タイプD」、「タイプE」、「タイプF」、「タイプG」のいずれか （該当しない場合は空欄） | CT2: 自然発火性液体 ※「1」 （該当しない場合は空欄） | CU2: 自然発火性固体 ※「１」 （該当しない場合は空欄） | CV2: 自己発熱性物質および混合物 ※「1」、「2」のいずれか （該当しない場合は空欄） | CW2: 水反応可燃性物質および混合物 ※「1」、「2」、「3」のいずれか （該当しない場合は空欄） | CX2: 酸化性液体 ※「1」、「2」、「3」のいずれか （該当しない場合は空欄） | CY2: 酸化性固体 ※「1」、「2」、「3」のいずれか （該当しない場合は空欄） | CZ2: 有機過酸化物 ※「タイプA」、「タイプB」、「タイプC」、「タイプD」、「タイプE」、「タイプF」、「タイプG」のいずれか （該当しない場合は空欄） | DA2: 金属腐食性化学品 ※「1」 （該当しない場合は空欄） | DB2: 鈍性化爆発物 ※「1」、「2」、「3」、「4」のいずれか （該当しない場合は空欄） | DC2: 急性毒性（経口） ※「1」、「2」、「3」、「4」、「5」のいずれか （該当しない場合は空欄） | DD2: 急性毒性（経皮） ※「1」、「2」、「3」、「4」、「5」のいずれか （該当しない場合は空欄） | DE2: 急性毒性（吸入：気体） ※「1」、「2」、「3」、「4」、「5」のいずれか （該当しない場合は空欄） | DF2: 急性毒性（吸入：蒸気） ※「1」、「2」、「3」、「4」、「5」のいずれか （該当しない場合は空欄） | DG2: 急性毒性（吸入：粉じん） ※「1」、「2」、「3」、「4」、「5」のいずれか （該当しない場合は空欄） | DH2: 急性毒性（吸入：ミスト） ※「1」、「2」、「3」、「4」、「5」のいずれか （該当しない場合は空欄） | DI2: 皮膚腐食性及び皮膚刺激性 ※「1」、「1A」、「1B」、「1C」、「2」、「3」のいずれか （該当しない場合は空欄） | DJ2: 眼に対する重篤な損傷性又は眼刺激性 ※「1」、「2A」、「2B」のいずれか （該当しない場合は空欄） | DK2: 呼吸器感作性 ※「1」、「1A」、「1B」のいずれか （該当しない場合は空欄） | DL2: 皮膚感作性 ※「1（1Aおよび1B)」 （該当しない場合は空欄） | DM2: 生殖細胞変異原性 ※「1A」、「1B」、「2」のいずれか （該当しない場合は空欄） | DN2: 発がん性 ※「1A」、「1B」、「2」のいずれか （該当しない場合は空欄） | DO2: 生殖毒性 ※「1A」、「1B」、「2」のいずれか （該当しない場合は空欄） | DP2: 生殖毒性（授乳区分） ※対象の場合は「○」、非対象の場合は空欄 | DQ2: 特定標的臓器毒性（単回ばく露） ※「1」、「2」、「3（気道刺激性）」、「3（麻酔作用）」のいずれか （該当しない場合は空欄） | DR2: 特定標的臓器毒性（反復ばく露） ※「1」、「2」のいずれか （該当しない場合は空欄） | DS2: 誤えん有害性 ※「1」、「2」のいずれか （該当しない場合は空欄） | DT2: 水生環境有害性 短期（急性） ※「1」、「2」、「3」のいずれか （該当しない場合は空欄） | DU2: 水生環境有害性 長期（慢性） ※「1」、「2」、「3」、「4」のいずれか （該当しない場合は空欄） | DV2: オゾン層への有害性 ※「1」 （該当しない場合は空欄）
B3: 一括更新不可 | C3: 一括更新不可 | BK3: =$BJ$3&"" | BL3: =$BJ$3&"" | BM3: =$BJ$3&"" | BN3: =$BJ$3&"" | BO3: =$BJ$3&"" | BP3: =$BJ$3&"" | BQ3: =$BJ$3&"" | BR3: =$BJ$3&"" | ... CC3: =$BJ$3&"" | CJ3: =CI$3&"" | CK3: =CJ$3&""
B4: シグマアルドリッチ(Millipore) | C4: 01318-5VL | D4: - | E4: Enterococcus faecium Selective Supplement, suitable for microbiology | H4: 5 | I4: VL | J4: 12100 | M4: 冷蔵 | N4: 指定なし | Q4: https://www.sigmaaldrich.com/JP/ja/search/01318?term=01318&type=product
B5: シグマアルドリッチ(Millipore) | C5: 01337-500G-F | D5: - | E5: Mitis Salivarius Agar, suitable for microbiology, NutriSelect(R) Plus | H5: 500 | I5: G | J5: 33500 | M5: 室温 | N5: 指定なし | Q5: https://www.sigmaaldrich.com/JP/ja/search/01337?term=01337&type=product
B6: シグマアルドリッチ(Millipore) | C6: 01497-500G-F | D6: - | E6: Yeast Extract Agar, suitable for microbiology, NutriSelect(R) Plus | H6: 500 | I6: G | J6: 27900 | M6: 室温 | N6: 指定なし | Q6: https://www.sigmaaldrich.com/JP/ja/search/01497?term=01497&type=product
B7: シグマアルドリッチ(Millipore) | C7: 01869-1KT | D7: - | E7: Hippurate Strips Kit, suitable for microbiology | F7: 67-64-1,71-36-3 | H7: 1 | I7: KT | J7: 12200 | M7: 冷蔵 | N7: 指定なし | Q7: https://www.sigmaaldrich.com/JP/ja/search/01869?term=01869&type=product | V7: ○
B8: シグマアルドリッチ(Millipore) | C8: 02538-500G-F | D8: - | E8: Raka-Ray Agar, suitable for microbiology, NutriSelect(R) Plus | H8: 500 | I8: G | J8: 45500 | M8: 室温 | N8: 指定なし | Q8: https://www.sigmaaldrich.com/JP/ja/search/02538?term=02538&type=product
B9: シグマアルドリッチ(Millipore) | C9: 03708-5VL | D9: - | E9: Listeria mono Enrichement Supplement I, suitable for microbiology | H9: 5 | I9: VL | J9: 49300 | M9: 冷凍 | N9: 指定なし | Q9: https://www.sigmaaldrich.com/JP/ja/search/03708?term=03708&type=product
B10: シグマアルドリッチ(Millipore) | C10: 03856-500G | D10: - | E10: Nutrient Broth, No. 4, suitable for microbiology, NutriSelect(R) Plus | H10: 500 | I10: G | J10: 36600 | M10: 室温 | N10: 指定なし | Q10: https://www.sigmaaldrich.com/JP/ja/search/03856?term=03856&type=product
B11: シグマアルドリッチ(Millipore) | C11: 04163-500G-F | D11: - | E11: Nutrient Agar No 2, Vegitone, suitable for microbiology, NutriSelect(R) Plus | H11: 500 | I11: G | J11: 16800 | M11: 室温 | N11: 指定なし | Q11: https://www.sigmaaldrich.com/JP/ja/search/04163?term=04163&type=product
B12: シグマアルドリッチ(Millipore) | C12: 04316-500G-F | D12: - | E12: Vegetable Extract No. 1, suitable for microbiology | H12: 500 | I12: G | J12: 16400 | M12: 室温 | N12: 指定なし | Q12: https://www.sigmaaldrich.com/JP/ja/search/04316?term=04316&type=product
B13: シグマアルドリッチ(Millipore) | C13: 04551-1KT-F | D13: - | E13: Schaeffer and Fulton Spore Stain Kit, for microscopic observation of bacteria and endospores | H13: 1 | I13: KT | J13: 16400 | M13: 室温 | N13: 指定なし | Q13: https://www.sigmaaldrich.com/JP/ja/search/04551?term=04551&type=product
B14: シグマアルドリッチ(Millipore) | C14: 04739-100STRIPS-F | D14: - | E14: Indoxyl Strips, suitable for microbiology | H14: 100 | I14: STRIPS | J14: 9600 | M14: 冷蔵 | N14: 指定なし | Q14: https://www.sigmaaldrich.com/JP/ja/search/04739?term=04739&type=product
B15: シグマアルドリッチ(Millipore) | C15: 05038-500G | D15: 寒天 | E15: Agar, suitable for microbiology | F15: 9002-18-0 | H15: 500 | I15: G | J15: 44600 | M15: 室温 | N15: 指定なし | Q15: https://www.sigmaaldrich.com/JP/ja/search/05038?term=05038&type=product
B16: シグマアルドリッチ(Millipore) | C16: 05039-50G | D16: 寒天 | E16: Agar, suitable for microbiology | F16: 9002-18-0 | H16: 50 | I16: G | J16: 2840 | M16: 室温 | N16: 指定なし | Q16: https://www.sigmaaldrich.com/JP/ja/search/05039?term=05039&type=product
B17: シグマアルドリッチ(Millipore) | C17: 05039-500G | D17: 寒天 | E17: Agar, suitable for microbiology | F17: 9002-18-0 | H17: 500 | I17: G | J17: 36300 | M17: 室温 | N17: 指定なし | Q17: https://www.sigmaaldrich.com/JP/ja/search/05039?term=05039&type=product
B18: シグマアルドリッチ(Millipore) | C18: 05040-100G | D18: 寒天 | E18: Agar, powder, suitable for microbiology | F18: 9002-18-0 | H18: 100 | I18: G | J18: 9230 | M18: 室温 | N18: 指定なし | Q18: https://www.sigmaaldrich.com/JP/ja/search/05040?term=05040&type=product
B19: シグマアルドリッチ(Millipore) | C19: 05040-250G | D19: 寒天 | E19: Agar, powder, suitable for microbiology | F19: 9002-18-0 | H19: 250 | I19: G | J19: 20200 | M19: 室温 | N19: 指定なし | Q19: https://www.sigmaaldrich.com/JP/ja/search/05040?term=05040&type=product
B20: シグマアルドリッチ(Millipore) | C20: 05040-1KG | D20: 寒天 | E20: Agar, powder, suitable for microbiology | F20: 9002-18-0 | H20: 1 | I20: KG | J20: 69600 | M20: 室温 | N20: 指定なし | Q20: https://www.sigmaaldrich.com/JP/ja/search/05040?term=05040&type=product
B21: シグマアルドリッチ(Millipore) | C21: 05138-500G-F | D21: - | E21: Vegetable Extract, suitable for microbiology | H21: 500 | I21: G | J21: 13200 | M21: 室温 | N21: 指定なし | Q21: https://www.sigmaaldrich.com/JP/ja/search/05138?term=05138&type=product
B22: シグマアルドリッチ(Millipore) | C22: 05290-25TESTS-F | D22: - | E22: Sterility Indicator (Radiation Sterilization), suitable for microbiology | H22: 25 | I22: TESTS | J22: 5270 | M22: 冷蔵 | N22: 指定なし | Q22: https://www.sigmaaldrich.com/JP/ja/search/05290?term=05290&type=product
B23: シグマアルドリッチ(Millipore) | C23: 05317-10EA | D23: - | E23: Immobilon(R)-FL PVDF membrane, pore size 0.45 μm | H23: 10 | I23: EA | J23: 29100 | M23: 室温 | N23: 指定なし | Q23: https://www.sigmaaldrich.com/JP/ja/sds/sigma/05317
B24: シグマアルドリッチ(Millipore) | C24: 05686-50DISCS-F | D24: - | E24: DMACA Indole Disks, suitable for microbiology | H24: 50 | I24: DISCS | J24: 9390 | M24: 冷蔵 | N24: 指定なし | Q24: https://www.sigmaaldrich.com/JP/ja/search/05686?term=05686&type=product
B25: シグマアルドリッチ(Millipore) | C25: 07233-500G-F | D25: - | E25: Maximum Recovery Diluent, suitable for microbiology, NutriSelect(R) Plus | H25: 500 | I25: G | J25: 12900 | M25: 室温 | N25: 指定なし | Q25: https://www.sigmaaldrich.com/JP/ja/search/07233?term=07233&type=product
B26: シグマアルドリッチ(Millipore) | C26: 07410-500G | D26: - | E26: Carbohydrate Consumption Broth, suitable for microbiology, NutriSelect(R) Plus | H26: 500 | I26: G | J26: 22200 | M26: 室温 | N26: 指定なし | Q26: https://www.sigmaaldrich.com/JP/ja/search/07410?term=07410&type=product
B27: シグマアルドリッチ(Millipore) | C27: 07411-10X25DISCS | D27: - | E27: Xylose Disks, suitable for microbiology | H27: 10 | I27: X25DISCS | J27: 17800 | M27: 冷蔵 | N27: 指定なし | Q27: https://www.sigmaaldrich.com/JP/ja/search/07411?term=07411&type=product
B28: シグマアルドリッチ(Millipore) | C28: 07436-500G-F | D28: - | E28: Vegetable Hydrolysate No. 2, suitable for microbiology | F28: 100209-45-8 | H28: 500 | I28: G | J28: 22100 | M28: 室温 | N28: 指定なし | Q28: https://www.sigmaaldrich.com/JP/ja/search/07436?term=07436&type=product
B29: シグマアルドリッチ(Millipore) | C29: 07751-500G | D29: - | E29: Peptone, mycological No. 2, suitable for microbiology | H29: 500 | I29: G | J29: 32300 | M29: 室温 | N29: 指定なし | Q29: https://www.sigmaaldrich.com/JP/ja/search/07751?term=07751&type=product
B30: シグマアルドリッチ(Millipore) | C30: 07770-25G | D30: - | E30: N,N-Dimethyl-p-phenylenediamine dihydrochloride, suitable for microbiology, >=99.0% | F30: 536-46-9 | H30: 25 | I30: G | J30: 19200 | M30: 室温(20℃±5℃) | N30: 指定なし | Q30: https://www.sigmaaldrich.com/JP/ja/search/07770?term=07770&type=product
B31: シグマアルドリッチ(Millipore) | C31: 07770-100G | D31: - | E31: N,N-Dimethyl-p-phenylenediamine dihydrochloride, suitable for microbiology, >=99.0% | F31: 536-46-9 | H31: 100 | I31: G | J31: 34000 | M31: 室温(20℃±5℃) | N31: 指定なし | Q31: https://www.sigmaaldrich.com/JP/ja/search/07770?term=07770&type=product
B32: シグマアルドリッチ(Millipore) | C32: 08069-500G | D32: - | E32: modified Tryptic Soy Broth- Dehydrated Culture Media, NutriSelect(R) Plus, with bile salts mixture, according to ISO 16654:2001, | H32: 500 | I32: G | J32: 30000 | M32: 室温 | N32: 指定なし | Q32: https://www.sigmaaldrich.com/JP/ja/search/08069?term=08069&type=product
B33: シグマアルドリッチ(Millipore) | C33: 08382-50DISCS-F | D33: - | E33: Bacitracin Disks, suitable for microbiology | H33: 50 | I33: DISCS | J33: 9390 | M33: 冷凍 | N33: 指定なし | Q33: https://www.sigmaaldrich.com/JP/ja/search/08382?term=08382&type=product
B34: シグマアルドリッチ(Millipore) | C34: 08482-50DISCS-F | D34: - | E34: X + V Factor Disks, suitable for microbiology | H34: 50 | I34: DISCS | J34: 9390 | M34: 冷蔵 | N34: 指定なし | Q34: https://www.sigmaaldrich.com/JP/ja/search/08482?term=08482&type=product
B35: シグマアルドリッチ(Millipore) | C35: 08582-10VL-F | D35: - | E35: Urea solution, suitable for microbiology, 40% in H2O | F35: 57-13-6 | H35: 10 | I35: VL | J35: 8970 | M35: 冷蔵 | N35: 指定なし | Q35: https://www.sigmaaldrich.com/JP/ja/search/08582?term=08582&type=product
A36: 4548173342757 | B36: シグマアルドリッチ(Millipore) | C36: 08714-100ML-F | D36: - | E36: Methyl Red solution, suitable for microbiology | F36: 493-52-7,64-17-5,71-23-8,67-56-1 | H36: 100 | I36: ML | J36: 7810 | M36: 室温(20℃±5℃) | N36: 指定なし | Q36: https://www.sigmaaldrich.com/JP/ja/search/08714?term=08714&type=product | V36: ○ | AA36: 第4類 | AB36: アルコール類
B37: シグマアルドリッチ(Millipore) | C37: 09136-500G | D37: - | E37: Tryptophan Broth, NutriSelect(R) Plus, suitable for microbiology | H37: 500 | I37: G | J37: 51000 | M37: 室温 | N37: 指定なし | Q37: https://www.sigmaaldrich.com/JP/ja/search/09136?term=09136&type=product
B38: シグマアルドリッチ(Millipore) | C38: 09182-1KG-F | D38: - | E38: Yeast Extract, for technical purposes (in fermentation) | F38: 8013-01-2 | H38: 1 | I38: KG | J38: 16400 | M38: 室温 | N38: 指定なし | Q38: https://www.sigmaaldrich.com/JP/ja/search/09182?term=09182&type=product
B39: シグマアルドリッチ(Millipore) | C39: 09182-5KG-F | D39: - | E39: Yeast Extract, for technical purposes (in fermentation) | F39: 8013-01-2 | H39: 5 | I39: KG | J39: 55200 | M39: 室温 | N39: 指定なし | Q39: https://www.sigmaaldrich.com/JP/ja/search/09182?term=09182&type=product
B40: シグマアルドリッチ(Millipore) | C40: 09678-100G | D40: - | E40: Ammonium bismuth citrate, base ingredient for culture media | F40: 31886-41-6 | H40: 100 | I40: G | J40: 26700 | M40: 室温 | N40: 指定なし | Q40: https://www.sigmaaldrich.com/JP/ja/search/09678?term=09678&type=product
...

Sheet Maker
A1: メーカー名
A2: ※必須 ※64文字以下
A3: シグマアルドリッチ(Millipore)

Sheet Ingredient
A1: 成分名 | B1: メーカー名
A2: ※必須 ※100文字以下 | B2: ※必須 ※100文字以下

Sheet Mix
A1: 管理番号 | B1: 混合物名 | C1: 有効期限 | D1: 備考 | E1: 成分名 | F1: 成分比率 | G1: 成分名 | H1: 成分比率 | I1: 成分名 | J1: 成分比率 | K1: 成分名 | L1: 成分比率 | M1: 成分名 | N1: 成分比率 | O1: 成分名 | P1: 成分比率 | Q1: 成分名 | R1: 成分比率 | S1: 成分名 | T1: 成分比率 | U1: 成分名 | V1: 成分比率 | W1: 成分名 | X1: 成分比率
A2: ※必須 ※32文字以下 | B2: ※必須 ※128文字以下 | C2: ※yyyy/MM/dd | D2: ※256文字以下 | F2: ※% | H2: ※% | J2: ※% | L2: ※% | N2: ※% | P2: ※% | R2: ※% | T2: ※% | V2: ※% | X2: ※%

Sheet 薬品マスタ重複チェック
A1: 薬品マスタ重複チェック
A2: 何行目 | B2: 重複 | C2: メーカー | D2: 型番 | E2: 和名 | F2: 英名 | G2: カタログ重量 | H2: (単位) | I2: 規格 | K2: 重複チェック用
A3: =IF(C3=0,"",ROW(A3)) | B3: =IF(K3="0 + 0","",IF(COUNTIF(K:K,K3)>1,"○","")) | C3: =Chemical!B4 -> 0 | D3: =Chemical!C4 -> 0 | E3: =Chemical!D4 -> 0 | F3: =Chemical!E4 -> 0 | G3: =IF(ISBLANK(Chemical!H4),"",Chemical!H4) | H3: =Chemical!I4 -> 0 | I3: =Chemical!G4 -> 0 | K3: =C3&" + "&D3 -> 0 + 0
A4: =IF(C4=0,"",ROW(A4)) | B4: =IF(K4="0 + 0","",IF(COUNTIF(K:K,K4)>1,"○","")) | C4: =Chemical!B5 -> 0 | D4: =Chemical!C5 -> 0 | E4: =Chemical!D5 -> 0 | F4: =Chemical!E5 -> 0 | G4: =IF(ISBLANK(Chemical!H5),"",Chemical!H5) | H4: =Chemical!I5 -> 0 | I4: =Chemical!G5 -> 0 | K4: =C4&" + "&D4 -> 0 + 0
A5: =IF(C5=0,"",ROW(A5)) | B5: =IF(K5="0 + 0","",IF(COUNTIF(K:K,K5)>1,"○","")) | C5: =Chemical!B6 -> 0 | D5: =Chemical!C6 -> 0 | E5: =Chemical!D6 -> 0 | F5: =Chemical!E6 -> 0 | G5: =IF(ISBLANK(Chemical!H6),"",Chemical!H6) | H5: =Chemical!I6 -> 0 | I5: =Chemical!G6 -> 0 | K5: =C5&" + "&D5 -> 0 + 0
A6: =IF(C6=0,"",ROW(A6)) | B6: =IF(K6="0 + 0","",IF(COUNTIF(K:K,K6)>1,"○","")) | C6: =Chemical!B7 -> 0 | D6: =Chemical!C7 -> 0 | E6: =Chemical!D7 -> 0 | F6: =Chemical!E7 -> 0 | G6: =IF(ISBLANK(Chemical!H7),"",Chemical!H7) | H6: =Chemical!I7 -> 0 | I6: =Chemical!G7 -> 0 | K6: =C6&" + "&D6 -> 0 + 0
A7: =IF(C7=0,"",ROW(A7)) | B7: =IF(K7="0 + 0","",IF(COUNTIF(K:K,K7)>1,"○","")) | C7: =Chemical!B8 -> 0 | D7: =Chemical!C8 -> 0 | E7: =Chemical!D8 -> 0 | F7: =Chemical!E8 -> 0 | G7: =IF(ISBLANK(Chemical!H8),"",Chemical!H8) | H7: =Chemical!I8 -> 0 | I7: =Chemical!G8 -> 0 | K7: =C7&" + "&D7 -> 0 + 0
A8: =IF(C8=0,"",ROW(A8)) | B8: =IF(K8="0 + 0","",IF(COUNTIF(K:K,K8)>1,"○","")) | C8: =Chemical!B9 -> 0 | D8: =Chemical!C9 -> 0 | E8: =Chemical!D9 -> 0 | F8: =Chemical!E9 -> 0 | G8: =IF(ISBLANK(Chemical!H9),"",Chemical!H9) | H8: =Chemical!I9 -> 0 | I8: =Chemical!G9 -> 0 | K8: =C8&" + "&D8 -> 0 + 0
A9: =IF(C9=0,"",ROW(A9)) | B9: =IF(K9="0 + 0","",IF(COUNTIF(K:K,K9)>1,"○","")) | C9: =Chemical!B10 -> 0 | D9: =Chemical!C10 -> 0 | E9: =Chemical!D10 -> 0 | F9: =Chemical!E10 -> 0 | G9: =IF(ISBLANK(Chemical!H10),"",Chemical!H10) | H9: =Chemical!I10 -> 0 | I9: =Chemical!G10 -> 0 | K9: =C9&" + "&D9 -> 0 + 0
A10: =IF(C10=0,"",ROW(A10)) | B10: =IF(K10="0 + 0","",IF(COUNTIF(K:K,K10)>1,"○","")) | C10: =Chemical!B11 -> 0 | D10: =Chemical!C11 -> 0 | E10: =Chemical!D11 -> 0 | F10: =Chemical!E11 -> 0 | G10: =IF(ISBLANK(Chemical!H11),"",Chemical!H11) | H10: =Chemical!I11 -> 0 | I10: =Chemical!G11 -> 0 | K10: =C10&" + "&D10 -> 0 + 0
A11: =IF(C11=0,"",ROW(A11)) | B11: =IF(K11="0 + 0","",IF(COUNTIF(K:K,K11)>1,"○","")) | C11: =Chemical!B12 -> 0 | D11: =Chemical!C12 -> 0 | E11: =Chemical!D12 -> 0 | F11: =Chemical!E12 -> 0 | G11: =IF(ISBLANK(Chemical!H12),"",Chemical!H12) | H11: =Chemical!I12 -> 0 | I11: =Chemical!G12 -> 0 | K11: =C11&" + "&D11 -> 0 + 0
A12: =IF(C12=0,"",ROW(A12)) | B12: =IF(K12="0 + 0","",IF(COUNTIF(K:K,K12)>1,"○","")) | C12: =Chemical!B13 -> 0 | D12: =Chemical!C13 -> 0 | E12: =Chemical!D13 -> 0 | F12: =Chemical!E13 -> 0 | G12: =IF(ISBLANK(Chemical!H13),"",Chemical!H13) | H12: =Chemical!I13 -> 0 | I12: =Chemical!G13 -> 0 | K12: =C12&" + "&D12 -> 0 + 0
A13: =IF(C13=0,"",ROW(A13)) | B13: =IF(K13="0 + 0","",IF(COUNTIF(K:K,K13)>1,"○","")) | C13: =Chemical!B14 -> 0 | D13: =Chemical!C14 -> 0 | E13: =Chemical!D14 -> 0 | F13: =Chemical!E14 -> 0 | G13: =IF(ISBLANK(Chemical!H14),"",Chemical!H14) | H13: =Chemical!I14 -> 0 | I13: =Chemical!G14 -> 0 | K13: =C13&" + "&D13 -> 0 + 0
A14: =IF(C14=0,"",ROW(A14)) | B14: =IF(K14="0 + 0","",IF(COUNTIF(K:K,K14)>1,"○","")) | C14: =Chemical!B15 -> 0 | D14: =Chemical!C15 -> 0 | E14: =Chemical!D15 -> 0 | F14: =Chemical!E15 -> 0 | G14: =IF(ISBLANK(Chemical!H15),"",Chemical!H15) | H14: =Chemical!I15 -> 0 | I14: =Chemical!G15 -> 0 | K14: =C14&" + "&D14 -> 0 + 0
... A4000: =IF(C4000=0,"",ROW(A4000)) | B4000: =IF(K4000="0 + 0","",IF(COUNTIF(K:K,K4000)>1,"○","")) | C4000: =Chemical!B4001 -> 0 | D4000: =Chemical!C4001 -> 0 | E4000: =Chemical!D4001 -> 0 | F4000: =Chemical!E4001 -> 0 | G4000: =IF(ISBLANK(Chemical!H4001),"",Chemical!H4001) | H4000: =Chemical!I4001 -> 0 | I4000: =Chemical!G4001 -> 0 | K4000: =C4000&" + "&D4000 -> 0 + 0

Sheet Sample_Ingredient
A1: 成分名 | B1: 化学式
A2: ※必須 ※100文字以下 | B2: ※必須 ※100文字以下
A3: 成分1 | B3: AB3C4
A4: 成分2 | B4: 3(DC4)EF

Sheet Sample_Mix
A1: 管理番号 | B1: 混合物名 | C1: 有効期限 | D1: 備考 | E1: 成分名 | F1: 成分比率 | G1: 成分名 | H1: 成分比率 | I1: 成分名 | J1: 成分比率 | K1: 成分名 | L1: 成分比率 | M1: 成分名 | N1: 成分比率 | O1: 成分名 | P1: 成分比率 | Q1: 成分名 | R1: 成分比率 | S1: 成分名 | T1: 成分比率 | U1: 成分名 | V1: 成分比率 | W1: 成分名 | X1: 成分比率
A2: ※必須 ※32文字以下 | B2: ※必須 ※128文字以下 | C2: ※yyyy/MM/dd | D2: ※256文字以下 | F2: ※% | H2: ※% | J2: ※% | L2: ※% | N2: ※% | P2: ※% | R2: ※% | T2: ※% | V2: ※% | X2: ※%
A3: 123456 | B3: 混合物サンプル | C3: 43860 | D3: サンプルです | E3: 成分1 | F3: 20.5 | G3: 成分2 | H3: 50.45 | I3: 成分3 | J3: 29.05
A4: abcdefg | B4: 混合物サンプルその2 | C4: 44341 | E4: 成分AAA | F4: 30.4 | G4: 成分BBB | H4: 69.6
